Workbook

Sheet Summary
A1: YouTube Tutorial Catalogue — Ollama NLP, LLM Jailbreaking/Red Teaming, NLP Pipelines & Deployment
A2: Source: crawled from YouTube search results on 24 Sep 2026 (41 search queries). View counts and upload ages are as shown on YouTube at crawl time.
A4: Category | B4: Sheet | C4: Videos | D4: Total views | E4: Ollama-based videos
A5: Ollama-based NLP Projects | B5: Ollama NLP Projects | C5: =COUNTA('Ollama NLP Projects'!B:B)-1 -> 138 | D5: =SUM('Ollama NLP Projects'!H:H) -> 15168799 | E5: =COUNTIF('Ollama NLP Projects'!F:F,"Yes") -> 123
A6: LLM Jailbreaking & Red Teaming | B6: LLM Jailbreak & Red Team | C6: =COUNTA('LLM Jailbreak & Red Team'!B:B)-1 -> 157 | D6: =SUM('LLM Jailbreak & Red Team'!H:H) -> 18024986 | E6: =COUNTIF('LLM Jailbreak & Red Team'!F:F,"Yes") -> 11
A7: NLP ML Pipelines & Deployment | B7: NLP Pipelines & Deploy | C7: =COUNTA('NLP Pipelines & Deploy'!B:B)-1 -> 162 | D7: =SUM('NLP Pipelines & Deploy'!H:H) -> 25312393 | E7: =COUNTIF('NLP Pipelines & Deploy'!F:F,"Yes") -> 5
A8: Unique videos (all categories) | C8: =COUNTA('All Videos (unique)'!B:B)-1 -> 443 | D8: =SUM('All Videos (unique)'!F:F) -> 49765178
A10: Sub-topic breakdown
A11: Ollama-based NLP Projects | C11: Videos
A12: AI Agents & Tool Calling | B12: AI Agents & Tool Calling | C12: =COUNTIF('Ollama NLP Projects'!D:D,B12) -> 11
A13: Chat with PDFs / Documents | B13: Chat with PDFs / Documents | C13: =COUNTIF('Ollama NLP Projects'!D:D,B13) -> 21
A14: Chatbots & Apps (Streamlit/Flask/FastAPI) | B14: Chatbots & Apps (Streamlit/Flask/FastAPI) | C14: =COUNTIF('Ollama NLP Projects'!D:D,B14) -> 20
A15: Classic NLP tasks (sentiment, classification, NER, extraction) | B15: Classic NLP tasks (sentiment, classification, NER, extraction) | C15: =COUNTIF('Ollama NLP Projects'!D:D,B15) -> 13
A16: Embeddings & Semantic Search | B16: Embeddings & Semantic Search | C16: =COUNTIF('Ollama NLP Projects'!D:D,B16) -> 9
A17: Fine-tuning / Custom Models (Modelfile) | B17: Fine-tuning / Custom Models (Modelfile) | C17: =COUNTIF('Ollama NLP Projects'!D:D,B17) -> 15
A18: Ollama Fundamentals / Courses | B18: Ollama Fundamentals / Courses | C18: =COUNTIF('Ollama NLP Projects'!D:D,B18) -> 24
A19: RAG (Retrieval-Augmented Generation) | B19: RAG (Retrieval-Augmented Generation) | C19: =COUNTIF('Ollama NLP Projects'!D:D,B19) -> 21
A20: Text Summarization | B20: Text Summarization | C20: =COUNTIF('Ollama NLP Projects'!D:D,B20) -> 4
A22: LLM Jailbreaking & Red Teaming | C22: Videos
A23: AI Red Teaming | B23: AI Red Teaming | C23: =COUNTIF('LLM Jailbreak & Red Team'!D:D,B23) -> 22
A24: Abliteration (removing refusals) | B24: Abliteration (removing refusals) | C24: =COUNTIF('LLM Jailbreak & Red Team'!D:D,B24) -> 12
A25: Defenses & Guardrails | B25: Defenses & Guardrails | C25: =COUNTIF('LLM Jailbreak & Red Team'!D:D,B25) -> 25
A26: Garak (LLM vulnerability scanner) | B26: Garak (LLM vulnerability scanner) | C26: =COUNTIF('LLM Jailbreak & Red Team'!D:D,B26) -> 15
A27: Jailbreaking Techniques & Research | B27: Jailbreaking Techniques & Research | C27: =COUNTIF('LLM Jailbreak & Red Team'!D:D,B27) -> 29
A28: Prompt Injection | B28: Prompt Injection | C28: =COUNTIF('LLM Jailbreak & Red Team'!D:D,B28) -> 22
A29: PyRIT (Microsoft red-teaming toolkit) | B29: PyRIT (Microsoft red-teaming toolkit) | C29: =COUNTIF('LLM Jailbreak & Red Team'!D:D,B29) -> 12
A30: Uncensored / Local Models (Ollama, LM Studio) | B30: Uncensored / Local Models (Ollama, LM Studio) | C30: =COUNTIF('LLM Jailbreak & Red Team'!D:D,B30) -> 20
A32: NLP ML Pipelines & Deployment | C32: Videos
A33: Cloud Deployment (AWS/SageMaker/GCP/Azure) | B33: Cloud Deployment (AWS/SageMaker/GCP/Azure) | C33: =COUNTIF('NLP Pipelines & Deploy'!D:D,B33) -> 31
A34: Deployment with FastAPI & Docker | B34: Deployment with FastAPI & Docker | C34: =COUNTIF('NLP Pipelines & Deploy'!D:D,B34) -> 10
A35: Deployment with Flask / Heroku | B35: Deployment with Flask / Heroku | C35: =COUNTIF('NLP Pipelines & Deploy'!D:D,B35) -> 9
A36: End-to-End NLP Projects (sentiment, classification, summarization) | B36: End-to-End NLP Projects (sentiment, classification, summarization) | C36: =COUNTIF('NLP Pipelines & Deploy'!D:D,B36) -> 17
A37: Fine-tuning (BERT / LLMs) | B37: Fine-tuning (BERT / LLMs) | C37: =COUNTIF('NLP Pipelines & Deploy'!D:D,B37) -> 18
A38: General ML / LLM Projects | B38: General ML / LLM Projects | C38: =COUNTIF('NLP Pipelines & Deploy'!D:D,B38) -> 17
A39: Hugging Face Models & Spaces | B39: Hugging Face Models & Spaces | C39: =COUNTIF('NLP Pipelines & Deploy'!D:D,B39) -> 10
A40: MLOps / End-to-End Pipelines | B40: MLOps / End-to-End Pipelines | C40: =COUNTIF('NLP Pipelines & Deploy'!D:D,B40) -> 19
A41: NLP Pipelines (spaCy / NLTK / preprocessing) | B41: NLP Pipelines (spaCy / NLTK / preprocessing) | C41: =COUNTIF('NLP Pipelines & Deploy'!D:D,B41) -> 31
A43: Notes
A44: • Each category sheet is sorted by sub-topic, then by views (most popular first). Use the filter arrows to narrow by sub-topic, video type, or Ollama usage.
A45: • "Video Type" and "Sub-topic" were assigned automatically from titles — treat them as a guide.
...

Sheet Ollama NLP Projects
A1: # | B1: Title | C1: Channel | D1: Sub-topic | E1: Video Type | F1: Uses Ollama? | G1: Duration | H1: Views | I1: Uploaded (approx.) | J1: Also listed in | K1: YouTube URL
A2: 1 | B2: Don't learn AI Agents without Learning these Fundamentals | C2: KodeKloud | D2: AI Agents & Tool Calling | E2: Explainer / Overview | F2: No | G2: 56:40 | H2: 1200000 | I2: 11 months ago | J2: NLP ML Pipelines & Deployment | K2: https://www.youtube.com/watch?v=ZaPbP9DwBOE
A3: 2 | B3: Python Advanced AI Agent Tutorial - LlamaIndex, Ollama and Multi-LLM! | C3: Tech With Tim | D3: AI Agents & Tool Calling | E3: Tutorial / Project | F3: Yes | G3: 53:57 | H3: 173000 | I3: 2 years ago | J3: — | K3: https://www.youtube.com/watch?v=JLmI0GJuGlY
A4: 3 | B4: Build a Local AI Agent in 10 Minutes using Python | C4: Tech With Tim | D4: AI Agents & Tool Calling | E4: Tutorial / Project | F4: No | G4: 8:08 | H4: 126000 | I4: 12 days ago | J4: — | K4: https://www.youtube.com/watch?v=ByWCsa8DbF8
A5: 4 | B5: Building a fully local research assistant from scratch with Ollama | C5: LangChain | D5: AI Agents & Tool Calling | E5: Tutorial / Project | F5: Yes | G5: 15:25 | H5: 66000 | I5: 1 year ago | J5: — | K5: https://www.youtube.com/watch?v=XGuTzHoqlj8
A6: 5 | B6: Coding Local AI Agent in Python (Ollama + LangGraph) | C6: NeuralNine | D6: AI Agents & Tool Calling | E6: Tutorial / Project | F6: Yes | G6: 50:43 | H6: 23000 | I6: 1 year ago | J6: — | K6: https://www.youtube.com/watch?v=9mLzD997JsU
A7: 6 | B7: Ollama Tool Calling: Integrate AI with ANY Python Function in 7 mins! | C7: Mervin Praison | D7: AI Agents & Tool Calling | E7: Explainer / Overview | F7: Yes | G7: 7:09 | H7: 19000 | I7: 1 year ago | J7: — | K7: https://www.youtube.com/watch?v=QzRPtorrZVo
A8: 7 | B8: Build a local AI Agent using n8n and Ollama | Open Source | Self-hosted | Ollama | AI | C8: BI Insights Inc | D8: AI Agents & Tool Calling | E8: Tutorial / Project | F8: Yes | G8: 5:26 | H8: 15000 | I8: 9 months ago | J8: — | K8: https://www.youtube.com/watch?v=qil5iBwd0IA
A9: 8 | B9: Build Your First AI Agent with LangChain V1 + Ollama (100% Local) | C9: AI by IG | D9: AI Agents & Tool Calling | E9: Tutorial / Project | F9: Yes | G9: 15:30 | H9: 818 | I9: 7 months ago | J9: — | K9: https://www.youtube.com/watch?v=b0HRiv-qMDM
A10: 9 | B10: Hands-on MCP Server development with LangChain AI Agent - Unlimited Local AI Agent using Ollama | C10: Deepak Mittal (AI Engineer) | D10: AI Agents & Tool Calling | E10: Tutorial / Project | F10: Yes | G10: 54:45 | H10: 709 | I10: 8 months ago | J10: — | K10: https://www.youtube.com/watch?v=5CnMYtseRKM
A11: 10 | B11: Build an AI Grocery Agent with LangChain & Ollama (Step-by-Step) | C11: honest pm iimbangalore | D11: AI Agents & Tool Calling | E11: Tutorial / Project | F11: Yes | G11: 1:04:22 | H11: 429 | I11: 4 months ago | J11: — | K11: https://www.youtube.com/watch?v=TEJDg6e9sdE
A12: 11 | B12: Build an Agentic AI Project with Ollama | C12: Byt a Byte | D12: AI Agents & Tool Calling | E12: Tutorial / Project | F12: Yes | G12: 1:22:26 | H12: 366 | I12: 1 year ago | J12: — | K12: https://www.youtube.com/watch?v=ZjsmPjNZMn8
A13: 12 | B13: Feed Your OWN Documents to a Local Large Language Model! | C13: Dave's Garage | D13: Chat with PDFs / Documents | E13: Explainer / Overview | F13: No | G13: 18:53 | H13: 970000 | I13: 1 year ago | J13: — | K13: https://www.youtube.com/watch?v=fFgyOucIFuk
... A139: 138 | B139: Bangla Text AI Summarizer: Ollama + Unsloth GGUF Deploy | C139: CS Inside | D139: Text Summarization | E139: Tutorial / Project | F139: Yes | G139: 2:30 | H139: 68 | I139: 10 months ago | J139: — | K139: https://www.youtube.com/watch?v=Bjy41MR6O8Y

Sheet LLM Jailbreak & Red Team
A1: # | B1: Title | C1: Channel | D1: Sub-topic | E1: Video Type | F1: Uses Ollama? | G1: Duration | H1: Views | I1: Uploaded (approx.) | J1: Also listed in | K1: YouTube URL
A2: 1 | B2: OWASP's Top 10 Ways to Attack LLMs: AI Vulnerabilities Exposed | C2: IBM Technology | D2: AI Red Teaming | E2: Explainer / Overview | F2: No | G2: 25:12 | H2: 307000 | I2: 6 months ago | J2: — | K2: https://www.youtube.com/watch?v=gUNXZMcd2jU
A3: 2 | B3: AI Red Teaming 101 – Full Course (Episodes 1-10) | C3: Microsoft Developer | D3: AI Red Teaming | E3: Full Course | F3: No | G3: 1:17:26 | H3: 42000 | I3: 1 year ago | J3: — | K3: https://www.youtube.com/watch?v=DwFVhFdD2fs
A4: 3 | B4: Agentic AI Red Teaming: The Hottest Cyber Skill of 2026 | C4: Cloud Security Guy | D4: AI Red Teaming | E4: Explainer / Overview | F4: No | G4: 16:04 | H4: 18000 | I4: 9 months ago | J4: — | K4: https://www.youtube.com/watch?v=SFOrnrxWTNw
A5: 4 | B5: Episode 1: What is AI Red Teaming? | AI Red Teaming 101 with Amanda and Gary | C5: Microsoft Developer | D5: AI Red Teaming | E5: Explainer / Overview | F5: No | G5: 6:16 | H5: 14000 | I5: 1 year ago | J5: — | K5: https://www.youtube.com/watch?v=DabrWAKNQZc
A6: 5 | B6: Open Source LLM Security Scanner — Full Setup + First Scan | C6: Taylor Walton | D6: AI Red Teaming | E6: Tutorial / Project | F6: No | G6: 17:37 | H6: 12000 | I6: 1 month ago | J6: — | K6: https://www.youtube.com/watch?v=EP7udDuF1cY
A7: 6 | B7: What is LLM Red Teaming? How Generative AI Safety Testing Works | C7: AI Lingua | D7: AI Red Teaming | E7: Explainer / Overview | F7: No | G7: 13:01 | H7: 7000 | I7: 1 year ago | J7: — | K7: https://www.youtube.com/watch?v=-OUmHDuaPPA
A8: 7 | B8: AI Red Team Course Introduction | C8: Red Nexus | D8: AI Red Teaming | E8: Full Course | F8: No | G8: 19:06 | H8: 4000 | I8: 2 weeks ago | J8: — | K8: https://www.youtube.com/watch?v=hxNUH7IrvTQ
A9: 8 | B9: Red Teaming AI: OWASP LLM Top 10 with Brian and Derek | C9: Antisyphon Training | D9: AI Red Teaming | E9: Explainer / Overview | F9: No | G9: 1:07:47 | H9: 4000 | I9: Streamed 6 months ago | J9: — | K9: https://www.youtube.com/watch?v=P-5DgsGkJbQ
A10: 9 | B10: How to get started with AI Red Teaming | C10: Hack The Box | D10: AI Red Teaming | E10: Tutorial / Project | F10: No | G10: 1:20 | H10: 3000 | I10: 1 year ago | J10: — | K10: https://www.youtube.com/watch?v=eLil3ZEs6nc
A11: 10 | B11: Learn Hands-On AI Security & Red Teaming | C11: Probably Private | D11: AI Red Teaming | E11: Tutorial / Project | F11: No | G11: 3:26 | H11: 3000 | I11: 11 months ago | J11: — | K11: https://www.youtube.com/watch?v=r30lMqmU-S0
A12: 11 | B12: How to Start an AI Red Teaming Career in 2026 (with free resources) | C12: Cloud Security Guy | D12: AI Red Teaming | E12: Tutorial / Project | F12: No | G12: 16:12 | H12: 2000 | I12: 1 month ago | J12: — | K12: https://www.youtube.com/watch?v=3YbWRuN2MTY
A13: 12 | B13: AI Red Teaming and Adversarial Prompt Testing | C13: raia | D13: AI Red Teaming | E13: Explainer / Overview | F13: No | G13: 4:40 | H13: 1000 | I13: 11 months ago | J13: — | K13: https://www.youtube.com/watch?v=7v-Sx6ON4OA
... A158: 157 | B158: 2 Ways to Use Uncensored AI (Ollama Local Machine & Web) | C158: Chinmaya | D158: Uncensored / Local Models (Ollama, LM Studio) | E158: Tutorial / Project | F158: Yes | G158: 9:55 | H158: 1000 | I158: 4 months ago | J158: — | K158: https://www.youtube.com/watch?v=LDuraZMu8_I

Sheet NLP Pipelines & Deploy
A1: # | B1: Title | C1: Channel | D1: Sub-topic | E1: Video Type | F1: Uses Ollama? | G1: Duration | H1: Views | I1: Uploaded (approx.) | J1: Also listed in | K1: YouTube URL
A2: 1 | B2: End To End Machine Learning Project Implementation Using AWS Sagemaker | C2: Krish Naik | D2: Cloud Deployment (AWS/SageMaker/GCP/Azure) | E2: Tutorial / Project | F2: No | G2: 40:25 | H2: 310000 | I2: 3 years ago | J2: — | K2: https://www.youtube.com/watch?v=Le-A72NjaWs
A3: 2 | B3: Build a Complete Medical Chatbot with LLMs, LangChain, Pinecone, Flask & AWS | C3: DSwithBappy | D3: Cloud Deployment (AWS/SageMaker/GCP/Azure) | E3: Full Course | F3: No | G3: 2:50:40 | H3: 272000 | I3: Streamed 1 year ago | J3: — | K3: https://www.youtube.com/watch?v=KnoVFU0yCUc
A4: 3 | B4: End To End Deep Learning Project Using MLOPS DVC Pipeline With Deployments Azure And AWS- Krish Naik | C4: Krish Naik | D4: Cloud Deployment (AWS/SageMaker/GCP/Azure) | E4: Full Course | F4: No | G4: 3:51:00 | H4: 268000 | I4: 3 years ago | J4: — | K4: https://www.youtube.com/watch?v=p1bfK8ZJgkE
A5: 4 | B5: How To Deploy A Machine Learning Model On AWS EC2 | AUG 2021 Updated | ML Model To Flask Website | C5: CampusX | D5: Cloud Deployment (AWS/SageMaker/GCP/Azure) | E5: Tutorial / Project | F5: No | G5: 39:29 | H5: 112000 | I5: 5 years ago | J5: — | K5: https://www.youtube.com/watch?v=_rwNTY5Mn40
A6: 5 | B6: How to Deploy ML Solutions with FastAPI, Docker, & AWS | C6: Shaw Talebi | D6: Cloud Deployment (AWS/SageMaker/GCP/Azure) | E6: Tutorial / Project | F6: No | G6: 28:48 | H6: 108000 | I6: 2 years ago | J6: — | K6: https://www.youtube.com/watch?v=pJ_nCklQ65w
A7: 6 | B7: MLOps Pipeline with Python, AWS, Docker – YouTube Viewer Sentiment | C7: freeCodeCamp.org | D7: Cloud Deployment (AWS/SageMaker/GCP/Azure) | E7: Full Course | F7: No | G7: 2:51:25 | H7: 100000 | I7: 1 year ago | J7: — | K7: https://www.youtube.com/watch?v=gwNPV882tkc
A8: 7 | B8: Deploy Your ML Models to Production at Scale with Amazon SageMaker | C8: Amazon Web Services | D8: Cloud Deployment (AWS/SageMaker/GCP/Azure) | E8: Tutorial / Project | F8: No | G8: 7:53 | H8: 88000 | I8: 7 years ago | J8: — | K8: https://www.youtube.com/watch?v=KFuc2KWrTHs
A9: 8 | B9: #3-Deployment Of Huggingface OpenSource LLM Models In AWS Sagemakers With Endpoints | C9: Krish Naik | D9: Cloud Deployment (AWS/SageMaker/GCP/Azure) | E9: Tutorial / Project | F9: No | G9: 22:32 | H9: 87000 | I9: 2 years ago | J9: — | K9: https://www.youtube.com/watch?v=U72q95dHpRo
A10: 9 | B10: Tutorial 9-End To End ML Project-Deployment In AWS Cloud Using CICD Pipelines | C10: Krish Naik | D10: Cloud Deployment (AWS/SageMaker/GCP/Azure) | E10: Tutorial / Project | F10: No | G10: 17:57 | H10: 86000 | I10: 3 years ago | J10: — | K10: https://www.youtube.com/watch?v=gbJn2Ls2QsI
A11: 10 | B11: Deep learning project end to end | Potato Disease Classification - 7 : Model Deployment To GCP | C11: codebasics | D11: Cloud Deployment (AWS/SageMaker/GCP/Azure) | E11: Tutorial / Project | F11: No | G11: 27:40 | H11: 80000 | I11: 5 years ago | J11: — | K11: https://www.youtube.com/watch?v=ra4j7yDlakQ
A12: 11 | B12: Amazon SageMaker overview | Amazon Web Services | C12: Amazon Web Services | D12: Cloud Deployment (AWS/SageMaker/GCP/Azure) | E12: Tutorial / Project | F12: No | G12: 9:01 | H12: 76000 | I12: 2 years ago | J12: — | K12: https://www.youtube.com/watch?v=mzkHGEyAPEw
A13: 12 | B13: Tutorial 4-Build,Train, Deploy Machine Learning Model In AWS SageMaker- Uploading Files In S3 Bucket | C13: Krish Naik | D13: Cloud Deployment (AWS/SageMaker/GCP/Azure) | E13: Tutorial / Project | F13: No | G13: 8:12 | H13: 75000 | I13: 6 years ago | J13: — | K13: https://www.youtube.com/watch?v=WIZeMBxtvgM
... A163: 162 | B163: Language Processing Pipelines in Spacy: NLP Hands-On-Tutorial L3 | C163: Dr. Sahinur Rahman Laskar | D163: NLP Pipelines (spaCy / NLTK / preprocessing) | E163: Tutorial / Project | F163: No | G163: 8:12 | H163: 30 | I163: 3 weeks ago | J163: — | K163: https://www.youtube.com/watch?v=tCy0P5AmHIY

Sheet All Videos (unique)
A1: # | B1: Title | C1: Channel | D1: Categories | E1: Duration | F1: Views | G1: Uploaded (approx.) | H1: YouTube URL
A2: 1 | B2: This new AI is powerful and uncensored… Let’s run it | C2: Fireship | D2: LLM Jailbreaking & Red Teaming | E2: 4:37 | F2: 2900000 | G2: 2 years ago | H2: https://www.youtube.com/watch?v=GyllRd2E6fg
A3: 2 | B3: Stanford CS229 I Machine Learning I Building Large Language Models (LLMs) | C3: Stanford Online | D3: NLP ML Pipelines & Deployment | E3: 1:44:31 | F3: 2800000 | G3: 2 years ago | H3: https://www.youtube.com/watch?v=9vM4p9NN0Ts
A4: 3 | B4: Run your own AI (but private) | C4: NetworkChuck | D4: LLM Jailbreaking & Red Teaming | E4: 22:13 | F4: 2600000 | G4: 2 years ago | H4: https://www.youtube.com/watch?v=WxYC9-hBM_g
A5: 4 | B5: Learn RAG From Scratch – Python AI Tutorial from a LangChain Engineer | C5: freeCodeCamp.org | D5: Ollama-based NLP Projects; NLP ML Pipelines & Deployment | E5: 2:33:11 | F5: 1700000 | G5: 2 years ago | H5: https://www.youtube.com/watch?v=sVcwVQRHIc8
A6: 5 | B6: run AI on your laptop....it's PRIVATE!! | C6: NetworkChuck | D6: Ollama-based NLP Projects | E6: 0:40 | F6: 1500000 | G6: 2 years ago | H6: https://www.youtube.com/watch?v=piFDfCaISk8
A7: 6 | B7: How To Jailbreak ChatGPT & Make It Do Whatever You Want | C7: Varun Mayya | D7: LLM Jailbreaking & Red Teaming | E7: 0:56 | F7: 1500000 | G7: 3 years ago | H7: https://www.youtube.com/watch?v=fw16D23TjJI
A8: 7 | B8: Hacking AI is TOO EASY (this should be illegal) | C8: NetworkChuck | D8: LLM Jailbreaking & Red Teaming | E8: 26:39 | F8: 1300000 | G8: 1 year ago | H8: https://www.youtube.com/watch?v=Qvx2sVgQ-u0
A9: 8 | B9: Learn Ollama in 15 Minutes - Run LLM Models Locally for FREE | C9: Tech With Tim | D9: Ollama-based NLP Projects; LLM Jailbreaking & Red Teaming | E9: 14:02 | F9: 1200000 | G9: 1 year ago | H9: https://www.youtube.com/watch?v=UtSSMs6ObqY
A10: 9 | B10: Don't learn AI Agents without Learning these Fundamentals | C10: KodeKloud | D10: Ollama-based NLP Projects; NLP ML Pipelines & Deployment | E10: 56:40 | F10: 1200000 | G10: 11 months ago | H10: https://www.youtube.com/watch?v=ZaPbP9DwBOE
A11: 10 | B11: Complete Agentic AI Course In 10 Hours- Langchain, Langgraph, RAG,Vectorless RAG, Guardrails,Evals | C11: Krish Naik | D11: Ollama-based NLP Projects | E11: 11:13:26 | F11: 1000000 | G11: 4 months ago | H11: https://www.youtube.com/watch?v=rV3HJ4LEZ7k
A12: 11 | B12: How To Run Private & Uncensored LLMs Offline | Dolphin Llama 3 | C12: Global Science Network | D12: LLM Jailbreaking & Red Teaming | E12: 14:31 | F12: 1000000 | G12: 1 year ago | H12: https://www.youtube.com/watch?v=eiMSapoeyaU
A13: 12 | B13: Feed Your OWN Documents to a Local Large Language Model! | C13: Dave's Garage | D13: Ollama-based NLP Projects | E13: 18:53 | F13: 970000 | G13: 1 year ago | H13: https://www.youtube.com/watch?v=fFgyOucIFuk
... A444: 443 | B444: Ollama setup in local and Run Fine-Tuned GGUF model in Ollama using Modelfile | C444: sahiam | D444: Ollama-based NLP Projects | E444: 4:05 | F444: 14 | G444: 12 days ago | H444: https://www.youtube.com/watch?v=zzlQ4CuNTB8
